Workbook
Name StakeholderList: Stakeholders!$A$3:$A$52

Sheet Instructions
A1: XAI Experience Quality (XEQ) Scale
A2: Data Analysis Tool Author: Craig Pirie
A3: This workbook is designed to help you collect, process, and analyse responses to the XEQ questionnaire. It provides a structured way to record participant data, calculate average scores, and visualise results across statements, dimensions, and stakeholder groups. The tool includes built-in formulas for scoring, confidence intervals, and chart generation. All sheets are interconnected to ensure consistency and minimise manual effort. Use this tool to explore how different groups perceive AI explanations, assess explanation quality, and identify areas for improvement.
A9: Data – Enter participant responses here. This is the only sheet that requires user input. Stakeholders – Define the stakeholder groups used throughout the workbook. Transform – Converts response data into a structured format for analysis. Updates automatically. Confidence Intervals – Calculates confidence intervals for scores per question, factor, and stakeholder. Results – Displays tables and charts showing mean scores and confidence intervals at multiple levels. Mapping – Links each question to an XEQ factor and holds values for dropdowns like confidence level. It is hidden to prevent accidental loss. All sheets work together to provide accurate, dynamic summaries of your XEQ data.

Sheet Stakeholders
A1: Stakeholders This table allows you to define and manage the stakeholder groups involved in your data collection and analysis. ✅ How to Use: Add a new stakeholder type in the next available row under the "Stakeholder" column. Once added, the stakeholder will automatically propagate across relevant sheets and formulas (e.g., filtering, summaries, charts, and calculations). ⚠️ Notes: Do not delete existing stakeholders if they are referenced in the data — this may break calculations or remove associated records. This sheet is linked to formulas across the workbook. Edits here will dynamically affect other areas .
A2: Stakeholders
A3: Course Leader
A4: Student
A5: Admin Assistant
A6: Demonstrator

Sheet Data
A1: Add your data here! Please enter participant responses according to the printed questionnaire. Each item should be rated on a 1 to 5 scale, where: 1 = Strong Disagreement and 5 = Strong Agreement with the statement. If a participant skips a question, leave the cell blank. Only numeric values from 1 to 5 are accepted — avoid symbols, text, or special characters, as these will disrupt the analysis. Stakeholders can be selected from a dropdown based on the list in the Stakeholders sheet. You may enter responses for up to 1000 participants. If you require more capacity, please extend the spreadsheet formulas accordingly. This is the only sheet that requires user input. A small set of sample data is included to demonstrate the format — feel free to delete it before entering real responses.
A2: Stakeholder Type | B2: Items
B3: 1 | C3: 2 | D3: 3 | E3: 4 | F3: 5 | G3: 6 | H3: 7 | I3: 8 | J3: 9 | K3: 10 | L3: 11 | M3: 12 | N3: 13 | O3: 14 | P3: 15 | Q3: 16 | R3: 17 | S3: 18
A4: Demonstrator | B4: 5 | C4: 5 | D4: 5 | E4: 5 | F4: 3 | G4: 4 | H4: 5 | I4: 4 | J4: 4 | K4: 5 | L4: 3 | M4: 3 | N4: 4 | O4: 1 | P4: 1 | Q4: 2 | R4: 2 | S4: 3
A5: Demonstrator | B5: 4 | C5: 3 | D5: 5 | E5: 3 | F5: 4 | G5: 3 | H5: 2 | I5: 4 | J5: 3 | K5: 4 | L5: 2 | M5: 4 | N5: 1 | O5: 4 | P5: 3 | Q5: 2 | R5: 3 | S5: 2
A6: Student | B6: 5 | C6: 2 | D6: 4 | E6: 4 | F6: 5 | G6: 4 | H6: 5 | I6: 4 | J6: 2 | K6: 3 | L6: 3 | M6: 5 | N6: 3 | O6: 3 | P6: 3 | Q6: 3 | R6: 3 | S6: 4
A7: Course Leader | B7: 3 | C7: 5 | D7: 1 | E7: 2 | F7: 2 | G7: 5 | H7: 5 | I7: 5 | J7: 3 | K7: 3 | L7: 5 | M7: 5 | N7: 4 | O7: 5 | P7: 4 | Q7: 4 | R7: 5 | S7: 5
A8: Course Leader | B8: 3 | C8: 5 | D8: 1 | E8: 3 | F8: 3 | G8: 5 | H8: 5 | I8: 3 | J8: 4 | K8: 5 | L8: 5 | M8: 3 | N8: 3 | O8: 3 | P8: 5 | Q8: 5 | R8: 4 | S8: 4
A9: Course Leader | B9: 4 | C9: 4 | D9: 1 | E9: 2 | F9: 4 | G9: 5 | H9: 5 | I9: 5 | J9: 5 | K9: 4 | L9: 4 | M9: 3 | N9: 4 | O9: 3 | P9: 5 | Q9: 5 | R9: 5 | S9: 3
A10: Demonstrator | B10: 4 | C10: 5 | D10: 1 | E10: 5 | F10: 3 | G10: 5 | H10: 4 | I10: 4 | J10: 4 | K10: 2 | L10: 5 | M10: 5 | N10: 5 | O10: 1 | P10: 5 | Q10: 1 | R10: 5 | S10: 5
A11: Demonstrator | B11: 2 | C11: 3 | D11: 5 | E11: 2 | F11: 2 | G11: 3 | H11: 3 | I11: 3 | J11: 2 | K11: 5 | L11: 2 | M11: 3 | N11: 4 | O11: 3 | P11: 4 | Q11: 3 | R11: 1 | S11: 3
A12: Admin Assistant | B12: 2 | C12: 3 | D12: 1 | E12: 1 | F12: 3 | G12: 3 | H12: 1 | I12: 3 | J12: 2 | K12: 2 | L12: 3 | M12: 1 | N12: 4 | O12: 1 | P12: 1 | Q12: 4 | R12: 2 | S12: 4
A13: Demonstrator | B13: 4 | C13: 2 | D13: 4 | E13: 5 | F13: 5 | G13: 5 | H13: 4 | I13: 2 | J13: 2 | K13: 3 | L13: 4 | M13: 2 | N13: 3 | O13: 3 | P13: 3 | Q13: 5 | R13: 2 | S13: 5
A14: Demonstrator | B14: 4 | C14: 4 | D14: 4 | E14: 4 | F14: 5 | G14: 5 | H14: 3 | I14: 4 | J14: 3 | K14: 1 | L14: 4 | M14: 3 | N14: 4 | O14: 1 | P14: 3 | Q14: 4 | R14: 1 | S14: 3
A15: Demonstrator | B15: 5 | C15: 3 | D15: 3 | E15: 5 | F15: 5 | G15: 5 | H15: 2 | I15: 3 | J15: 5 | K15: 4 | L15: 4 | M15: 5 | N15: 4 | O15: 5 | P15: 3 | Q15: 5 | R15: 4 | S15: 4
... A258: Demonstrator | B258: 4 | C258: 2 | D258: 2 | E258: 4 | F258: 3 | G258: 5 | H258: 2 | I258: 4 | J258: 3 | K258: 2 | L258: 3 | M258: 4 | N258: 3 | O258: 5 | P258: 4 | Q258: 4 | R258: 4 | S258: 2

Sheet Transform
A1: Transformed Data This sheet reshapes raw response data into a structured format for analysis. Used as the source for aggregated calculations and charts across the workbook or you can use it for your own statistical analysis. Do not edit manually — this sheet updates automatically based on the data and mapping sheets.
A2: Stakeholder Type | B2: Items | V2: Factor Means Per Person | AB2: System XEQ Score | AI2: Stakeholder Type | AJ2: Stakeholder Scores
B3: 1 | C3: 2 | D3: 3 | E3: 4 | F3: 5 | G3: 6 | H3: 7 | I3: 8 | J3: 9 | K3: 10 | L3: 11 | M3: 12 | N3: 13 | O3: 14 | P3: 15 | Q3: 16 | R3: 17 | S3: 18 | V3: Utility | W3: Satisfaction | X3: Effectiveness | AB3: Utility | AC3: Satisfaction | AD3: Effectiveness | AF3: System | AJ3: Utility | AK3: Satisfaction | AL3: Effectiveness
A4: =IF(Data!A4>0,Data!A4,"") | B4: =IF(Data!B4>0,Data!B4,"") | C4: =IF(Data!C4>0,Data!C4,"") | D4: =IF(Data!D4>0,Data!D4,"") | E4: =IF(Data!E4>0,Data!E4,"") | F4: =IF(Data!F4>0,Data!F4,"") | G4: =IF(Data!G4>0,Data!G4,"") | H4: =IF(Data!H4>0,Data!H4,"") | ... S4: =IF(Data!S4>0,Data!S4,"") | V4: =IF(COUNT(D4,J4,K4,L4,M4,O4)>0,AVERAGE(D4,J4,K4,L4,M4,O4),"") | W4: =IF(COUNT(C4,F4,G4,N4,Q4)>0,AVERAGE(C4,F4,G4,N4,Q4),"") | X4: =IF(COUNT(B4,E4,H4,I4,P4,R4,S4)>0,AVERAGE(B4,E4,H4,I4,P4,R4,S4),"") | AB4: =AVERAGE(V4:V1004) | AC4: =AVERAGE(W4:W1004) | AD4: =AVERAGE(X4:X1004) | AF4: =AVERAGE(AB4:AD4) | AI4: {=_xlfn._xlws.FILTER(StakeholderList, StakeholderList<>"")} | AJ4: =IFERROR(AVERAGEIF($A$4:$A$1004,AI4,$V$4:$V$1004),"") | AK4: =IFERROR(AVERAGEIF($A$4:$A$1004,AI4,$W$4:$W$1004),"") | AL4: =IFERROR(AVERAGEIF($A$4:$A$1004,AI4,$X$4:$X$1004),"")
A5: =IF(Data!A5>0,Data!A5,"") | B5: =IF(Data!B5>0,Data!B5,"") | C5: =IF(Data!C5>0,Data!C5,"") | D5: =IF(Data!D5>0,Data!D5,"") | E5: =IF(Data!E5>0,Data!E5,"") | F5: =IF(Data!F5>0,Data!F5,"") | G5: =IF(Data!G5>0,Data!G5,"") | H5: =IF(Data!H5>0,Data!H5,"") | ... S5: =IF(Data!S5>0,Data!S5,"") | V5: =IF(COUNT(D5,J5,K5,L5,M5,O5)>0,AVERAGE(D5,J5,K5,L5,M5,O5),"") | W5: =IF(COUNT(C5,F5,G5,N5,Q5)>0,AVERAGE(C5,F5,G5,N5,Q5),"") | X5: =IF(COUNT(B5,E5,H5,I5,P5,R5,S5)>0,AVERAGE(B5,E5,H5,I5,P5,R5,S5),"") | AI5: Student | AJ5: =IFERROR(AVERAGEIF($A$4:$A$1004,AI5,$V$4:$V$1004),"") | AK5: =IFERROR(AVERAGEIF($A$4:$A$1004,AI5,$W$4:$W$1004),"") | AL5: =IFERROR(AVERAGEIF($A$4:$A$1004,AI5,$X$4:$X$1004),"")
A6: =IF(Data!A6>0,Data!A6,"") | B6: =IF(Data!B6>0,Data!B6,"") | C6: =IF(Data!C6>0,Data!C6,"") | D6: =IF(Data!D6>0,Data!D6,"") | E6: =IF(Data!E6>0,Data!E6,"") | F6: =IF(Data!F6>0,Data!F6,"") | G6: =IF(Data!G6>0,Data!G6,"") | H6: =IF(Data!H6>0,Data!H6,"") | ... S6: =IF(Data!S6>0,Data!S6,"") | V6: =IF(COUNT(D6,J6,K6,L6,M6,O6)>0,AVERAGE(D6,J6,K6,L6,M6,O6),"") | W6: =IF(COUNT(C6,F6,G6,N6,Q6)>0,AVERAGE(C6,F6,G6,N6,Q6),"") | X6: =IF(COUNT(B6,E6,H6,I6,P6,R6,S6)>0,AVERAGE(B6,E6,H6,I6,P6,R6,S6),"") | AI6: Admin Assistant | AJ6: =IFERROR(AVERAGEIF($A$4:$A$1004,AI6,$V$4:$V$1004),"") | AK6: =IFERROR(AVERAGEIF($A$4:$A$1004,AI6,$W$4:$W$1004),"") | AL6: =IFERROR(AVERAGEIF($A$4:$A$1004,AI6,$X$4:$X$1004),"")
A7: =IF(Data!A7>0,Data!A7,"") | B7: =IF(Data!B7>0,Data!B7,"") | C7: =IF(Data!C7>0,Data!C7,"") | D7: =IF(Data!D7>0,Data!D7,"") | E7: =IF(Data!E7>0,Data!E7,"") | F7: =IF(Data!F7>0,Data!F7,"") | G7: =IF(Data!G7>0,Data!G7,"") | H7: =IF(Data!H7>0,Data!H7,"") | ... S7: =IF(Data!S7>0,Data!S7,"") | V7: =IF(COUNT(D7,J7,K7,L7,M7,O7)>0,AVERAGE(D7,J7,K7,L7,M7,O7),"") | W7: =IF(COUNT(C7,F7,G7,N7,Q7)>0,AVERAGE(C7,F7,G7,N7,Q7),"") | X7: =IF(COUNT(B7,E7,H7,I7,P7,R7,S7)>0,AVERAGE(B7,E7,H7,I7,P7,R7,S7),"") | AI7: Demonstrator | AJ7: =IFERROR(AVERAGEIF($A$4:$A$1004,AI7,$V$4:$V$1004),"") | AK7: =IFERROR(AVERAGEIF($A$4:$A$1004,AI7,$W$4:$W$1004),"") | AL7: =IFERROR(AVERAGEIF($A$4:$A$1004,AI7,$X$4:$X$1004),"")
A8: =IF(Data!A8>0,Data!A8,"") | B8: =IF(Data!B8>0,Data!B8,"") | C8: =IF(Data!C8>0,Data!C8,"") | D8: =IF(Data!D8>0,Data!D8,"") | E8: =IF(Data!E8>0,Data!E8,"") | F8: =IF(Data!F8>0,Data!F8,"") | G8: =IF(Data!G8>0,Data!G8,"") | H8: =IF(Data!H8>0,Data!H8,"") | ... S8: =IF(Data!S8>0,Data!S8,"") | V8: =IF(COUNT(D8,J8,K8,L8,M8,O8)>0,AVERAGE(D8,J8,K8,L8,M8,O8),"") | W8: =IF(COUNT(C8,F8,G8,N8,Q8)>0,AVERAGE(C8,F8,G8,N8,Q8),"") | X8: =IF(COUNT(B8,E8,H8,I8,P8,R8,S8)>0,AVERAGE(B8,E8,H8,I8,P8,R8,S8),"") | AJ8: =IFERROR(AVERAGEIF($A$4:$A$1004,AI8,$V$4:$V$1004),"") | AK8: =IFERROR(AVERAGEIF($A$4:$A$1004,AI8,$W$4:$W$1004),"") | AL8: =IFERROR(AVERAGEIF($A$4:$A$1004,AI8,$X$4:$X$1004),"")
A9: =IF(Data!A9>0,Data!A9,"") | B9: =IF(Data!B9>0,Data!B9,"") | C9: =IF(Data!C9>0,Data!C9,"") | D9: =IF(Data!D9>0,Data!D9,"") | E9: =IF(Data!E9>0,Data!E9,"") | F9: =IF(Data!F9>0,Data!F9,"") | G9: =IF(Data!G9>0,Data!G9,"") | H9: =IF(Data!H9>0,Data!H9,"") | ... S9: =IF(Data!S9>0,Data!S9,"") | V9: =IF(COUNT(D9,J9,K9,L9,M9,O9)>0,AVERAGE(D9,J9,K9,L9,M9,O9),"") | W9: =IF(COUNT(C9,F9,G9,N9,Q9)>0,AVERAGE(C9,F9,G9,N9,Q9),"") | X9: =IF(COUNT(B9,E9,H9,I9,P9,R9,S9)>0,AVERAGE(B9,E9,H9,I9,P9,R9,S9),"") | AJ9: =IFERROR(AVERAGEIF($A$4:$A$1004,AI9,$V$4:$V$1004),"") | AK9: =IFERROR(AVERAGEIF($A$4:$A$1004,AI9,$W$4:$W$1004),"") | AL9: =IFERROR(AVERAGEIF($A$4:$A$1004,AI9,$X$4:$X$1004),"")
A10: =IF(Data!A10>0,Data!A10,"") | B10: =IF(Data!B10>0,Data!B10,"") | C10: =IF(Data!C10>0,Data!C10,"") | D10: =IF(Data!D10>0,Data!D10,"") | E10: =IF(Data!E10>0,Data!E10,"") | F10: =IF(Data!F10>0,Data!F10,"") | G10: =IF(Data!G10>0,Data!G10,"") | H10: =IF(Data!H10>0,Data!H10,"") | ... S10: =IF(Data!S10>0,Data!S10,"") | V10: =IF(COUNT(D10,J10,K10,L10,M10,O10)>0,AVERAGE(D10,J10,K10,L10,M10,O10),"") | W10: =IF(COUNT(C10,F10,G10,N10,Q10)>0,AVERAGE(C10,F10,G10,N10,Q10),"") | X10: =IF(COUNT(B10,E10,H10,I10,P10,R10,S10)>0,AVERAGE(B10,E10,H10,I10,P10,R10,S10),"") | AJ10: =IFERROR(AVERAGEIF($A$4:$A$1004,AI10,$V$4:$V$1004),"") | AK10: =IFERROR(AVERAGEIF($A$4:$A$1004,AI10,$W$4:$W$1004),"") | AL10: =IFERROR(AVERAGEIF($A$4:$A$1004,AI10,$X$4:$X$1004),"")
A11: =IF(Data!A11>0,Data!A11,"") | B11: =IF(Data!B11>0,Data!B11,"") | C11: =IF(Data!C11>0,Data!C11,"") | D11: =IF(Data!D11>0,Data!D11,"") | E11: =IF(Data!E11>0,Data!E11,"") | F11: =IF(Data!F11>0,Data!F11,"") | G11: =IF(Data!G11>0,Data!G11,"") | H11: =IF(Data!H11>0,Data!H11,"") | ... S11: =IF(Data!S11>0,Data!S11,"") | V11: =IF(COUNT(D11,J11,K11,L11,M11,O11)>0,AVERAGE(D11,J11,K11,L11,M11,O11),"") | W11: =IF(COUNT(C11,F11,G11,N11,Q11)>0,AVERAGE(C11,F11,G11,N11,Q11),"") | X11: =IF(COUNT(B11,E11,H11,I11,P11,R11,S11)>0,AVERAGE(B11,E11,H11,I11,P11,R11,S11),"") | AJ11: =IFERROR(AVERAGEIF($A$4:$A$1004,AI11,$V$4:$V$1004),"") | AK11: =IFERROR(AVERAGEIF($A$4:$A$1004,AI11,$W$4:$W$1004),"") | AL11: =IFERROR(AVERAGEIF($A$4:$A$1004,AI11,$X$4:$X$1004),"")
A12: =IF(Data!A12>0,Data!A12,"") | B12: =IF(Data!B12>0,Data!B12,"") | C12: =IF(Data!C12>0,Data!C12,"") | D12: =IF(Data!D12>0,Data!D12,"") | E12: =IF(Data!E12>0,Data!E12,"") | F12: =IF(Data!F12>0,Data!F12,"") | G12: =IF(Data!G12>0,Data!G12,"") | H12: =IF(Data!H12>0,Data!H12,"") | ... S12: =IF(Data!S12>0,Data!S12,"") | V12: =IF(COUNT(D12,J12,K12,L12,M12,O12)>0,AVERAGE(D12,J12,K12,L12,M12,O12),"") | W12: =IF(COUNT(C12,F12,G12,N12,Q12)>0,AVERAGE(C12,F12,G12,N12,Q12),"") | X12: =IF(COUNT(B12,E12,H12,I12,P12,R12,S12)>0,AVERAGE(B12,E12,H12,I12,P12,R12,S12),"") | AJ12: =IFERROR(AVERAGEIF($A$4:$A$1004,AI12,$V$4:$V$1004),"") | AK12: =IFERROR(AVERAGEIF($A$4:$A$1004,AI12,$W$4:$W$1004),"") | AL12: =IFERROR(AVERAGEIF($A$4:$A$1004,AI12,$X$4:$X$1004),"")
A13: =IF(Data!A13>0,Data!A13,"") | B13: =IF(Data!B13>0,Data!B13,"") | C13: =IF(Data!C13>0,Data!C13,"") | D13: =IF(Data!D13>0,Data!D13,"") | E13: =IF(Data!E13>0,Data!E13,"") | F13: =IF(Data!F13>0,Data!F13,"") | G13: =IF(Data!G13>0,Data!G13,"") | H13: =IF(Data!H13>0,Data!H13,"") | ... S13: =IF(Data!S13>0,Data!S13,"") | V13: =IF(COUNT(D13,J13,K13,L13,M13,O13)>0,AVERAGE(D13,J13,K13,L13,M13,O13),"") | W13: =IF(COUNT(C13,F13,G13,N13,Q13)>0,AVERAGE(C13,F13,G13,N13,Q13),"") | X13: =IF(COUNT(B13,E13,H13,I13,P13,R13,S13)>0,AVERAGE(B13,E13,H13,I13,P13,R13,S13),"") | AJ13: =IFERROR(AVERAGEIF($A$4:$A$1004,AI13,$V$4:$V$1004),"") | AK13: =IFERROR(AVERAGEIF($A$4:$A$1004,AI13,$W$4:$W$1004),"") | AL13: =IFERROR(AVERAGEIF($A$4:$A$1004,AI13,$X$4:$X$1004),"")
A14: =IF(Data!A14>0,Data!A14,"") | B14: =IF(Data!B14>0,Data!B14,"") | C14: =IF(Data!C14>0,Data!C14,"") | D14: =IF(Data!D14>0,Data!D14,"") | E14: =IF(Data!E14>0,Data!E14,"") | F14: =IF(Data!F14>0,Data!F14,"") | G14: =IF(Data!G14>0,Data!G14,"") | H14: =IF(Data!H14>0,Data!H14,"") | ... S14: =IF(Data!S14>0,Data!S14,"") | V14: =IF(COUNT(D14,J14,K14,L14,M14,O14)>0,AVERAGE(D14,J14,K14,L14,M14,O14),"") | W14: =IF(COUNT(C14,F14,G14,N14,Q14)>0,AVERAGE(C14,F14,G14,N14,Q14),"") | X14: =IF(COUNT(B14,E14,H14,I14,P14,R14,S14)>0,AVERAGE(B14,E14,H14,I14,P14,R14,S14),"") | AJ14: =IFERROR(AVERAGEIF($A$4:$A$1004,AI14,$V$4:$V$1004),"") | AK14: =IFERROR(AVERAGEIF($A$4:$A$1004,AI14,$W$4:$W$1004),"") | AL14: =IFERROR(AVERAGEIF($A$4:$A$1004,AI14,$X$4:$X$1004),"")
A15: =IF(Data!A15>0,Data!A15,"") | B15: =IF(Data!B15>0,Data!B15,"") | C15: =IF(Data!C15>0,Data!C15,"") | D15: =IF(Data!D15>0,Data!D15,"") | E15: =IF(Data!E15>0,Data!E15,"") | F15: =IF(Data!F15>0,Data!F15,"") | G15: =IF(Data!G15>0,Data!G15,"") | H15: =IF(Data!H15>0,Data!H15,"") | ... S15: =IF(Data!S15>0,Data!S15,"") | V15: =IF(COUNT(D15,J15,K15,L15,M15,O15)>0,AVERAGE(D15,J15,K15,L15,M15,O15),"") | W15: =IF(COUNT(C15,F15,G15,N15,Q15)>0,AVERAGE(C15,F15,G15,N15,Q15),"") | X15: =IF(COUNT(B15,E15,H15,I15,P15,R15,S15)>0,AVERAGE(B15,E15,H15,I15,P15,R15,S15),"") | AJ15: =IFERROR(AVERAGEIF($A$4:$A$1004,AI15,$V$4:$V$1004),"") | AK15: =IFERROR(AVERAGEIF($A$4:$A$1004,AI15,$W$4:$W$1004),"") | AL15: =IFERROR(AVERAGEIF($A$4:$A$1004,AI15,$X$4:$X$1004),"")
A16: =IF(Data!A16>0,Data!A16,"") | B16: =IF(Data!B16>0,Data!B16,"") | C16: =IF(Data!C16>0,Data!C16,"") | D16: =IF(Data!D16>0,Data!D16,"") | E16: =IF(Data!E16>0,Data!E16,"") | F16: =IF(Data!F16>0,Data!F16,"") | G16: =IF(Data!G16>0,Data!G16,"") | H16: =IF(Data!H16>0,Data!H16,"") | ... S16: =IF(Data!S16>0,Data!S16,"") | V16: =IF(COUNT(D16,J16,K16,L16,M16,O16)>0,AVERAGE(D16,J16,K16,L16,M16,O16),"") | W16: =IF(COUNT(C16,F16,G16,N16,Q16)>0,AVERAGE(C16,F16,G16,N16,Q16),"") | X16: =IF(COUNT(B16,E16,H16,I16,P16,R16,S16)>0,AVERAGE(B16,E16,H16,I16,P16,R16,S16),"") | AJ16: =IFERROR(AVERAGEIF($A$4:$A$1004,AI16,$V$4:$V$1004),"") | AK16: =IFERROR(AVERAGEIF($A$4:$A$1004,AI16,$W$4:$W$1004),"") | AL16: =IFERROR(AVERAGEIF($A$4:$A$1004,AI16,$X$4:$X$1004),"")
A17: =IF(Data!A17>0,Data!A17,"") | B17: =IF(Data!B17>0,Data!B17,"") | C17: =IF(Data!C17>0,Data!C17,"") | D17: =IF(Data!D17>0,Data!D17,"") | E17: =IF(Data!E17>0,Data!E17,"") | F17: =IF(Data!F17>0,Data!F17,"") | G17: =IF(Data!G17>0,Data!G17,"") | H17: =IF(Data!H17>0,Data!H17,"") | ... S17: =IF(Data!S17>0,Data!S17,"") | V17: =IF(COUNT(D17,J17,K17,L17,M17,O17)>0,AVERAGE(D17,J17,K17,L17,M17,O17),"") | W17: =IF(COUNT(C17,F17,G17,N17,Q17)>0,AVERAGE(C17,F17,G17,N17,Q17),"") | X17: =IF(COUNT(B17,E17,H17,I17,P17,R17,S17)>0,AVERAGE(B17,E17,H17,I17,P17,R17,S17),"") | AJ17: =IFERROR(AVERAGEIF($A$4:$A$1004,AI17,$V$4:$V$1004),"") | AK17: =IFERROR(AVERAGEIF($A$4:$A$1004,AI17,$W$4:$W$1004),"") | AL17: =IFERROR(AVERAGEIF($A$4:$A$1004,AI17,$X$4:$X$1004),"")
A18: =IF(Data!A18>0,Data!A18,"") | B18: =IF(Data!B18>0,Data!B18,"") | C18: =IF(Data!C18>0,Data!C18,"") | D18: =IF(Data!D18>0,Data!D18,"") | E18: =IF(Data!E18>0,Data!E18,"") | F18: =IF(Data!F18>0,Data!F18,"") | G18: =IF(Data!G18>0,Data!G18,"") | H18: =IF(Data!H18>0,Data!H18,"") | ... S18: =IF(Data!S18>0,Data!S18,"") | V18: =IF(COUNT(D18,J18,K18,L18,M18,O18)>0,AVERAGE(D18,J18,K18,L18,M18,O18),"") | W18: =IF(COUNT(C18,F18,G18,N18,Q18)>0,AVERAGE(C18,F18,G18,N18,Q18),"") | X18: =IF(COUNT(B18,E18,H18,I18,P18,R18,S18)>0,AVERAGE(B18,E18,H18,I18,P18,R18,S18),"") | AJ18: =IFERROR(AVERAGEIF($A$4:$A$1004,AI18,$V$4:$V$1004),"") | AK18: =IFERROR(AVERAGEIF($A$4:$A$1004,AI18,$W$4:$W$1004),"") | AL18: =IFERROR(AVERAGEIF($A$4:$A$1004,AI18,$X$4:$X$1004),"")
A19: =IF(Data!A19>0,Data!A19,"") | B19: =IF(Data!B19>0,Data!B19,"") | C19: =IF(Data!C19>0,Data!C19,"") | D19: =IF(Data!D19>0,Data!D19,"") | E19: =IF(Data!E19>0,Data!E19,"") | F19: =IF(Data!F19>0,Data!F19,"") | G19: =IF(Data!G19>0,Data!G19,"") | H19: =IF(Data!H19>0,Data!H19,"") | ... S19: =IF(Data!S19>0,Data!S19,"") | V19: =IF(COUNT(D19,J19,K19,L19,M19,O19)>0,AVERAGE(D19,J19,K19,L19,M19,O19),"") | W19: =IF(COUNT(C19,F19,G19,N19,Q19)>0,AVERAGE(C19,F19,G19,N19,Q19),"") | X19: =IF(COUNT(B19,E19,H19,I19,P19,R19,S19)>0,AVERAGE(B19,E19,H19,I19,P19,R19,S19),"") | AJ19: =IFERROR(AVERAGEIF($A$4:$A$1004,AI19,$V$4:$V$1004),"") | AK19: =IFERROR(AVERAGEIF($A$4:$A$1004,AI19,$W$4:$W$1004),"") | AL19: =IFERROR(AVERAGEIF($A$4:$A$1004,AI19,$X$4:$X$1004),"")
... A1004: =IF(Data!A1004>0,Data!A1004,"") | B1004: =IF(Data!B1004>0,Data!B1004,"") | C1004: =IF(Data!C1004>0,Data!C1004,"") | D1004: =IF(Data!D1004>0,Data!D1004,"") | E1004: =IF(Data!E1004>0,Data!E1004,"") | F1004: =IF(Data!F1004>0,Data!F1004,"") | G1004: =IF(Data!G1004>0,Data!G1004,"") | H1004: =IF(Data!H1004>0,Data!H1004,"") | ... S1004: =IF(Data!S1004>0,Data!S1004,"") | V1004: =IF(COUNT(D1004,J1004,K1004,L1004,M1004,O1004)>0,AVERAGE(D1004,J1004,K1004,L1004,M1004,O1004),"") | W1004: =IF(COUNT(C1004,F1004,G1004,N1004,Q1004)>0,AVERAGE(C1004,F1004,G1004,N1004,Q1004),"") | X1004: =IF(COUNT(B1004,E1004,H1004,I1004,P1004,R1004,S1004)>0,AVERAGE(B1004,E1004,H1004,I1004,P1004,R1004,S1004),"") | AJ1004: =IFERROR(AVERAGEIF($A$4:$A$1004,AI1004,$V$4:$V$1004),"") | AK1004: =IFERROR(AVERAGEIF($A$4:$A$1004,AI1004,$W$4:$W$1004),"") | AL1004: =IFERROR(AVERAGEIF($A$4:$A$1004,AI1004,$X$4:$X$1004),"")

Sheet Results
A1: Results This sheet shows a breakdown of XEQ scores in three views: (1) By Statement – Average score for each statement with error bars (2) By Factor – Mean scores across the three XEQ factors (3) By Stakeholder – Factor scores grouped by stakeholder type Each table has a matching chart with confidence intervals. Data updates automatically — no manual input needed.
J2: XEQ Factors (Mean and Variance) | P2: XEQ Stakeholder Scores
A3: Item | B3: Mean | C3: Variance | D3: Std. Dev. | E3: No. | F3: Factor | J3: Factor | K3: Mean | L3: Variance | M3: Std.Dev | P3: Stakeholder | Q3: Utility Mean | R3: Satisfaction Mean | S3: Effectiveness Mean
A4: 1 | B4: =AVERAGE(Transform!B4:B1004) | C4: =VAR(Transform!B4:B1004) | D4: =SQRT(C4) | E4: =COUNTA(Data!B4:B1004) | F4: =_xlfn.XLOOKUP(A4, Mapping!A:A, Mapping!B:B, "Unknown") | J4: Utility | K4: =AVERAGE(Transform!V4:V1004) | L4: =VAR(Transform!V4:V1004) | M4: =SQRT(L4) | P4: {=_xlfn._xlws.FILTER(Stakeholders!A3:A50, Stakeholders!A3:A50<>"")} | Q4: =IFERROR(AVERAGEIF(Transform!$A$4:$A$1004,Transform!AI4,Transform!$V$4:$V$1004),"") | R4: =IFERROR(AVERAGEIF(Transform!$A$4:$A$1004,Transform!AI4,Transform!$W$4:$W$1004),"") | S4: =IFERROR(AVERAGEIF(Transform!$A$4:$A$1004,Transform!AI4,Transform!$X$4:$X$1004),"")
A5: 2 | B5: =AVERAGE(Transform!C4:C1004) | C5: =VAR(Transform!C4:C1004) | D5: =SQRT(C5) | E5: =COUNTA(Data!C4:C1004) | F5: =_xlfn.XLOOKUP(A5, Mapping!A:A, Mapping!B:B, "Unknown") | J5: Satisfaction | K5: =AVERAGE(Transform!W4:W1004) | L5: =VAR(Transform!W4:W1004) | M5: =SQRT(L5) | P5: Student | Q5: =IFERROR(AVERAGEIF(Transform!$A$4:$A$1004,Transform!AI5,Transform!$V$4:$V$1004),"") | R5: =IFERROR(AVERAGEIF(Transform!$A$4:$A$1004,Transform!AI5,Transform!$W$4:$W$1004),"") | S5: =IFERROR(AVERAGEIF(Transform!$A$4:$A$1004,Transform!AI5,Transform!$X$4:$X$1004),"")
A6: 3 | B6: =AVERAGE(Transform!D4:D1004) | C6: =VAR(Transform!D4:D1004) | D6: =SQRT(C6) | E6: =COUNTA(Data!D4:D1004) | F6: =_xlfn.XLOOKUP(A6, Mapping!A:A, Mapping!B:B, "Unknown") | J6: Effectiveness | K6: =AVERAGE(Transform!X4:X1004) | L6: =VAR(Transform!X4:X1004) | M6: =SQRT(L6) | P6: Admin Assistant | Q6: =IFERROR(AVERAGEIF(Transform!$A$4:$A$1004,Transform!AI6,Transform!$V$4:$V$1004),"") | R6: =IFERROR(AVERAGEIF(Transform!$A$4:$A$1004,Transform!AI6,Transform!$W$4:$W$1004),"") | S6: =IFERROR(AVERAGEIF(Transform!$A$4:$A$1004,Transform!AI6,Transform!$X$4:$X$1004),"")
A7: 4 | B7: =AVERAGE(Transform!E4:E1004) | C7: =VAR(Transform!E4:E1004) | D7: =SQRT(C7) | E7: =COUNTA(Data!E4:E1004) | F7: =_xlfn.XLOOKUP(A7, Mapping!A:A, Mapping!B:B, "Unknown") | P7: Demonstrator | Q7: =IFERROR(AVERAGEIF(Transform!$A$4:$A$1004,Transform!AI7,Transform!$V$4:$V$1004),"") | R7: =IFERROR(AVERAGEIF(Transform!$A$4:$A$1004,Transform!AI7,Transform!$W$4:$W$1004),"") | S7: =IFERROR(AVERAGEIF(Transform!$A$4:$A$1004,Transform!AI7,Transform!$X$4:$X$1004),"")
A8: 5 | B8: =AVERAGE(Transform!F4:F1004) | C8: =VAR(Transform!F4:F1004) | D8: =SQRT(C8) | E8: =COUNTA(Data!F4:F1004) | F8: =_xlfn.XLOOKUP(A8, Mapping!A:A, Mapping!B:B, "Unknown") | J8: System | K8: =AVERAGE(Transform!B4:S1004) | L8: =VAR(Transform!B4:S1004) | M8: =SQRT(L8) | Q8: =IFERROR(AVERAGEIF(Transform!$A$4:$A$1004,Transform!AI8,Transform!$V$4:$V$1004),"") | R8: =IFERROR(AVERAGEIF(Transform!$A$4:$A$1004,Transform!AI8,Transform!$W$4:$W$1004),"") | S8: =IFERROR(AVERAGEIF(Transform!$A$4:$A$1004,Transform!AI8,Transform!$X$4:$X$1004),"")
A9: 6 | B9: =AVERAGE(Transform!G4:G1004) | C9: =VAR(Transform!G4:G1004) | D9: =SQRT(C9) | E9: =COUNTA(Data!G4:G1004) | F9: =_xlfn.XLOOKUP(A9, Mapping!A:A, Mapping!B:B, "Unknown") | Q9: =IFERROR(AVERAGEIF(Transform!$A$4:$A$1004,Transform!AI9,Transform!$V$4:$V$1004),"") | R9: =IFERROR(AVERAGEIF(Transform!$A$4:$A$1004,Transform!AI9,Transform!$W$4:$W$1004),"") | S9: =IFERROR(AVERAGEIF(Transform!$A$4:$A$1004,Transform!AI9,Transform!$X$4:$X$1004),"")
A10: 7 | B10: =AVERAGE(Transform!H4:H1004) | C10: =VAR(Transform!H4:H1004) | D10: =SQRT(C10) | E10: =COUNTA(Data!H4:H1004) | F10: =_xlfn.XLOOKUP(A10, Mapping!A:A, Mapping!B:B, "Unknown") | Q10: =IFERROR(AVERAGEIF(Transform!$A$4:$A$1004,Transform!AI10,Transform!$V$4:$V$1004),"") | R10: =IFERROR(AVERAGEIF(Transform!$A$4:$A$1004,Transform!AI10,Transform!$W$4:$W$1004),"") | S10: =IFERROR(AVERAGEIF(Transform!$A$4:$A$1004,Transform!AI10,Transform!$X$4:$X$1004),"")
A11: 8 | B11: =AVERAGE(Transform!I4:I1004) | C11: =VAR(Transform!I4:I1004) | D11: =SQRT(C11) | E11: =COUNTA(Data!I4:I1004) | F11: =_xlfn.XLOOKUP(A11, Mapping!A:A, Mapping!B:B, "Unknown") | Q11: =IFERROR(AVERAGEIF(Transform!$A$4:$A$1004,Transform!AI11,Transform!$V$4:$V$1004),"") | R11: =IFERROR(AVERAGEIF(Transform!$A$4:$A$1004,Transform!AI11,Transform!$W$4:$W$1004),"") | S11: =IFERROR(AVERAGEIF(Transform!$A$4:$A$1004,Transform!AI11,Transform!$X$4:$X$1004),"")
A12: 9 | B12: =AVERAGE(Transform!J4:J1004) | C12: =VAR(Transform!J4:J1004) | D12: =SQRT(C12) | E12: =COUNTA(Data!J4:J1004) | F12: =_xlfn.XLOOKUP(A12, Mapping!A:A, Mapping!B:B, "Unknown") | Q12: =IFERROR(AVERAGEIF(Transform!$A$4:$A$1004,Transform!AI12,Transform!$V$4:$V$1004),"") | R12: =IFERROR(AVERAGEIF(Transform!$A$4:$A$1004,Transform!AI12,Transform!$W$4:$W$1004),"") | S12: =IFERROR(AVERAGEIF(Transform!$A$4:$A$1004,Transform!AI12,Transform!$X$4:$X$1004),"")
A13: 10 | B13: =AVERAGE(Transform!K4:K1004) | C13: =VAR(Transform!K4:K1004) | D13: =SQRT(C13) | E13: =COUNTA(Data!K4:K1004) | F13: =_xlfn.XLOOKUP(A13, Mapping!A:A, Mapping!B:B, "Unknown") | Q13: =IFERROR(AVERAGEIF(Transform!$A$4:$A$1004,Transform!AI13,Transform!$V$4:$V$1004),"") | R13: =IFERROR(AVERAGEIF(Transform!$A$4:$A$1004,Transform!AI13,Transform!$W$4:$W$1004),"") | S13: =IFERROR(AVERAGEIF(Transform!$A$4:$A$1004,Transform!AI13,Transform!$X$4:$X$1004),"")
A14: 11 | B14: =AVERAGE(Transform!L4:L1004) | C14: =VAR(Transform!L4:L1004) | D14: =SQRT(C14) | E14: =COUNTA(Data!L4:L1004) | F14: =_xlfn.XLOOKUP(A14, Mapping!A:A, Mapping!B:B, "Unknown") | Q14: =IFERROR(AVERAGEIF(Transform!$A$4:$A$1004,Transform!AI14,Transform!$V$4:$V$1004),"") | R14: =IFERROR(AVERAGEIF(Transform!$A$4:$A$1004,Transform!AI14,Transform!$W$4:$W$1004),"") | S14: =IFERROR(AVERAGEIF(Transform!$A$4:$A$1004,Transform!AI14,Transform!$X$4:$X$1004),"")
A15: 12 | B15: =AVERAGE(Transform!M4:M1004) | C15: =VAR(Transform!M4:M1004) | D15: =SQRT(C15) | E15: =COUNTA(Data!M4:M1004) | F15: =_xlfn.XLOOKUP(A15, Mapping!A:A, Mapping!B:B, "Unknown") | Q15: =IFERROR(AVERAGEIF(Transform!$A$4:$A$1004,Transform!AI15,Transform!$V$4:$V$1004),"") | R15: =IFERROR(AVERAGEIF(Transform!$A$4:$A$1004,Transform!AI15,Transform!$W$4:$W$1004),"") | S15: =IFERROR(AVERAGEIF(Transform!$A$4:$A$1004,Transform!AI15,Transform!$X$4:$X$1004),"")
A16: 13 | B16: =AVERAGE(Transform!N4:N1004) | C16: =VAR(Transform!N4:N1004) | D16: =SQRT(C16) | E16: =COUNTA(Data!N4:N1004) | F16: =_xlfn.XLOOKUP(A16, Mapping!A:A, Mapping!B:B, "Unknown") | Q16: =IFERROR(AVERAGEIF(Transform!$A$4:$A$1004,Transform!AI16,Transform!$V$4:$V$1004),"") | R16: =IFERROR(AVERAGEIF(Transform!$A$4:$A$1004,Transform!AI16,Transform!$W$4:$W$1004),"") | S16: =IFERROR(AVERAGEIF(Transform!$A$4:$A$1004,Transform!AI16,Transform!$X$4:$X$1004),"")
A17: 14 | B17: =AVERAGE(Transform!O4:O1004) | C17: =VAR(Transform!O4:O1004) | D17: =SQRT(C17) | E17: =COUNTA(Data!O4:O1004) | F17: =_xlfn.XLOOKUP(A17, Mapping!A:A, Mapping!B:B, "Unknown") | Q17: =IFERROR(AVERAGEIF(Transform!$A$4:$A$1004,Transform!AI17,Transform!$V$4:$V$1004),"") | R17: =IFERROR(AVERAGEIF(Transform!$A$4:$A$1004,Transform!AI17,Transform!$W$4:$W$1004),"") | S17: =IFERROR(AVERAGEIF(Transform!$A$4:$A$1004,Transform!AI17,Transform!$X$4:$X$1004),"")
A18: 15 | B18: =AVERAGE(Transform!P4:P1004) | C18: =VAR(Transform!P4:P1004) | D18: =SQRT(C18) | E18: =COUNTA(Data!P4:P1004) | F18: =_xlfn.XLOOKUP(A18, Mapping!A:A, Mapping!B:B, "Unknown") | Q18: =IFERROR(AVERAGEIF(Transform!$A$4:$A$1004,Transform!AI18,Transform!$V$4:$V$1004),"") | R18: =IFERROR(AVERAGEIF(Transform!$A$4:$A$1004,Transform!AI18,Transform!$W$4:$W$1004),"") | S18: =IFERROR(AVERAGEIF(Transform!$A$4:$A$1004,Transform!AI18,Transform!$X$4:$X$1004),"")
A19: 16 | B19: =AVERAGE(Transform!Q4:Q1004) | C19: =VAR(Transform!Q4:Q1004) | D19: =SQRT(C19) | E19: =COUNTA(Data!Q4:Q1004) | F19: =_xlfn.XLOOKUP(A19, Mapping!A:A, Mapping!B:B, "Unknown") | Q19: =IFERROR(AVERAGEIF(Transform!$A$4:$A$1004,Transform!AI19,Transform!$V$4:$V$1004),"") | R19: =IFERROR(AVERAGEIF(Transform!$A$4:$A$1004,Transform!AI19,Transform!$W$4:$W$1004),"") | S19: =IFERROR(AVERAGEIF(Transform!$A$4:$A$1004,Transform!AI19,Transform!$X$4:$X$1004),"")
A20: 17 | B20: =AVERAGE(Transform!R4:R1004) | C20: =VAR(Transform!R4:R1004) | D20: =SQRT(C20) | E20: =COUNTA(Data!R4:R1004) | F20: =_xlfn.XLOOKUP(A20, Mapping!A:A, Mapping!B:B, "Unknown") | Q20: =IFERROR(AVERAGEIF(Transform!$A$4:$A$1004,Transform!AI20,Transform!$V$4:$V$1004),"") | R20: =IFERROR(AVERAGEIF(Transform!$A$4:$A$1004,Transform!AI20,Transform!$W$4:$W$1004),"") | S20: =IFERROR(AVERAGEIF(Transform!$A$4:$A$1004,Transform!AI20,Transform!$X$4:$X$1004),"")
A21: 18 | B21: =AVERAGE(Transform!S4:S1004) | C21: =VAR(Transform!S4:S1004) | D21: =SQRT(C21) | E21: =COUNTA(Data!S4:S1004) | F21: =_xlfn.XLOOKUP(A21, Mapping!A:A, Mapping!B:B, "Unknown") | Q21: =IFERROR(AVERAGEIF(Transform!$A$4:$A$1004,Transform!AI21,Transform!$V$4:$V$1004),"") | R21: =IFERROR(AVERAGEIF(Transform!$A$4:$A$1004,Transform!AI21,Transform!$W$4:$W$1004),"") | S21: =IFERROR(AVERAGEIF(Transform!$A$4:$A$1004,Transform!AI21,Transform!$X$4:$X$1004),"")
Q22: =IFERROR(AVERAGEIF(Transform!$A$4:$A$1004,Transform!AI22,Transform!$V$4:$V$1004),"") | R22: =IFERROR(AVERAGEIF(Transform!$A$4:$A$1004,Transform!AI22,Transform!$W$4:$W$1004),"") | S22: =IFERROR(AVERAGEIF(Transform!$A$4:$A$1004,Transform!AI22,Transform!$X$4:$X$1004),"")
Q23: =IFERROR(AVERAGEIF(Transform!$A$4:$A$1004,Transform!AI23,Transform!$V$4:$V$1004),"") | R23: =IFERROR(AVERAGEIF(Transform!$A$4:$A$1004,Transform!AI23,Transform!$W$4:$W$1004),"") | S23: =IFERROR(AVERAGEIF(Transform!$A$4:$A$1004,Transform!AI23,Transform!$X$4:$X$1004),"")
Q24: =IFERROR(AVERAGEIF(Transform!$A$4:$A$1004,Transform!AI24,Transform!$V$4:$V$1004),"") | R24: =IFERROR(AVERAGEIF(Transform!$A$4:$A$1004,Transform!AI24,Transform!$W$4:$W$1004),"") | S24: =IFERROR(AVERAGEIF(Transform!$A$4:$A$1004,Transform!AI24,Transform!$X$4:$X$1004),"")
Q25: =IFERROR(AVERAGEIF(Transform!$A$4:$A$1004,Transform!AI25,Transform!$V$4:$V$1004),"") | R25: =IFERROR(AVERAGEIF(Transform!$A$4:$A$1004,Transform!AI25,Transform!$W$4:$W$1004),"") | S25: =IFERROR(AVERAGEIF(Transform!$A$4:$A$1004,Transform!AI25,Transform!$X$4:$X$1004),"")
Q26: =IFERROR(AVERAGEIF(Transform!$A$4:$A$1004,Transform!AI26,Transform!$V$4:$V$1004),"") | R26: =IFERROR(AVERAGEIF(Transform!$A$4:$A$1004,Transform!AI26,Transform!$W$4:$W$1004),"") | S26: =IFERROR(AVERAGEIF(Transform!$A$4:$A$1004,Transform!AI26,Transform!$X$4:$X$1004),"")
Q27: =IFERROR(AVERAGEIF(Transform!$A$4:$A$1004,Transform!AI27,Transform!$V$4:$V$1004),"") | R27: =IFERROR(AVERAGEIF(Transform!$A$4:$A$1004,Transform!AI27,Transform!$W$4:$W$1004),"") | S27: =IFERROR(AVERAGEIF(Transform!$A$4:$A$1004,Transform!AI27,Transform!$X$4:$X$1004),"")
Q28: =IFERROR(AVERAGEIF(Transform!$A$4:$A$1004,Transform!AI28,Transform!$V$4:$V$1004),"") | R28: =IFERROR(AVERAGEIF(Transform!$A$4:$A$1004,Transform!AI28,Transform!$W$4:$W$1004),"") | S28: =IFERROR(AVERAGEIF(Transform!$A$4:$A$1004,Transform!AI28,Transform!$X$4:$X$1004),"")
Q29: =IFERROR(AVERAGEIF(Transform!$A$4:$A$1004,Transform!AI29,Transform!$V$4:$V$1004),"") | R29: =IFERROR(AVERAGEIF(Transform!$A$4:$A$1004,Transform!AI29,Transform!$W$4:$W$1004),"") | S29: =IFERROR(AVERAGEIF(Transform!$A$4:$A$1004,Transform!AI29,Transform!$X$4:$X$1004),"")
Q30: =IFERROR(AVERAGEIF(Transform!$A$4:$A$1004,Transform!AI30,Transform!$V$4:$V$1004),"") | R30: =IFERROR(AVERAGEIF(Transform!$A$4:$A$1004,Transform!AI30,Transform!$W$4:$W$1004),"") | S30: =IFERROR(AVERAGEIF(Transform!$A$4:$A$1004,Transform!AI30,Transform!$X$4:$X$1004),"")
Q31: =IFERROR(AVERAGEIF(Transform!$A$4:$A$1004,Transform!AI31,Transform!$V$4:$V$1004),"") | R31: =IFERROR(AVERAGEIF(Transform!$A$4:$A$1004,Transform!AI31,Transform!$W$4:$W$1004),"") | S31: =IFERROR(AVERAGEIF(Transform!$A$4:$A$1004,Transform!AI31,Transform!$X$4:$X$1004),"")
Q32: =IFERROR(AVERAGEIF(Transform!$A$4:$A$1004,Transform!AI32,Transform!$V$4:$V$1004),"") | R32: =IFERROR(AVERAGEIF(Transform!$A$4:$A$1004,Transform!AI32,Transform!$W$4:$W$1004),"") | S32: =IFERROR(AVERAGEIF(Transform!$A$4:$A$1004,Transform!AI32,Transform!$X$4:$X$1004),"")
Q33: =IFERROR(AVERAGEIF(Transform!$A$4:$A$1004,Transform!AI33,Transform!$V$4:$V$1004),"") | R33: =IFERROR(AVERAGEIF(Transform!$A$4:$A$1004,Transform!AI33,Transform!$W$4:$W$1004),"") | S33: =IFERROR(AVERAGEIF(Transform!$A$4:$A$1004,Transform!AI33,Transform!$X$4:$X$1004),"")
... Q53: =IFERROR(AVERAGEIF(Transform!$A$4:$A$1004,Transform!AI53,Transform!$V$4:$V$1004),"") | R53: =IFERROR(AVERAGEIF(Transform!$A$4:$A$1004,Transform!AI53,Transform!$W$4:$W$1004),"") | S53: =IFERROR(AVERAGEIF(Transform!$A$4:$A$1004,Transform!AI53,Transform!$X$4:$X$1004),"")
Q54: =IFERROR(AVERAGEIF(Transform!$A$4:$A$1004, Transform!AI54, Transform!$V$4:$V$1004), "") | R54: =IFERROR(AVERAGEIF(Transform!$A$4:$A$1004,Transform!AI54,Transform!$W$4:$W$1004), "") | S54: =IFERROR(AVERAGEIF(Transform!$A$4:$A$1004,Transform!AI54,Transform!$X$4:$X$1004), "") | T54: =IFERROR(AVERAGEIF(Transform!$A$4:$A$1004, Transform!AI54, Transform!$Y$4:$Y$1004), "")

Sheet Confidence Intervals
A1: Confidence Intervals This sheet calculates confidence intervals for XEQ scores at three levels: (1) Per Statement – Confidence interval for each individual question (2) Per Factor – Interval for each XEQ factor (3) Per Stakeholder – Interval for each stakeholder group's factor scores Intervals adjust based on the selected confidence level, below (default=95%). The higher the confidence level, the more precise the estimate of scale mean is and helps you to trust your results more. All other data updates automatically — no manual changes required.
A2: Choose Your Confidence Level: | B2: 95 | C2: Alpha: | D2: =1-(B2/100) | K2: XEQ Score Per Factor
A3: XEQ Score Per Item | K3: Factor | L3: Mean | M3: Variance | N3: Std. Dev. | O3: No. | P3: Confidence | Q3: Confidence Interval
A4: Item | B4: Mean | C4: Variance | D4: Std. Dev. | E4: No. | F4: Confidence | G4: Confidence Interval | K4: Utility | L4: =AVERAGE(Transform!V$4:V$1004) | M4: =VAR(Transform!V4:V1004) | N4: =SQRT(M4) | O4: =COUNT(Transform!V4:V1004) | P4: =IF(AND(ISNUMBER(N4),O4>0),CONFIDENCE(D2,N4,O4),"") | Q4: =IF(AND(ISNUMBER(L4),ISNUMBER(P4)),L4-P4,"") | R4: =IF(AND(ISNUMBER(L4),ISNUMBER(P4)),L4+P4,"")
A5: 1 | B5: =AVERAGE(Transform!B4:B1004) | C5: =VAR(Transform!B4:B1004) | D5: =SQRT(C5) | E5: =COUNTA(Data!B4:B1004) | F5: =CONFIDENCE(D2,D5, E5) | G5: =B5-F5 | H5: =B5+F5 | K5: Satisfaction | L5: =AVERAGE(Transform!W$4:W$1004) | M5: =VAR(Transform!W4:W1004) | N5: =SQRT(M5) | O5: =COUNT(Transform!W4:W1004) | P5: =IF(AND(ISNUMBER(N5),O5>0),CONFIDENCE(D2,N5,O5),"") | Q5: =IF(AND(ISNUMBER(L5),ISNUMBER(P5)),L5-P5,"") | R5: =IF(AND(ISNUMBER(L5),ISNUMBER(P5)),L5+P5,"")
A6: 2 | B6: =AVERAGE(Transform!C4:C1004) | C6: =VAR(Transform!C4:C1004) | D6: =SQRT(C6) | E6: =COUNTA(Data!C4:C1004) | F6: =CONFIDENCE(D2,D6, E6) | G6: =B6-F6 | H6: =B6+F6 | K6: Effectiveness | L6: =AVERAGE(Transform!X$4:X$1004) | M6: =VAR(Transform!X4:X1004) | N6: =SQRT(M6) | O6: =COUNT(Transform!X4:X1004) | P6: =IF(AND(ISNUMBER(N6),O6>0),CONFIDENCE(D2,N6,O6),"") | Q6: =IF(AND(ISNUMBER(L6),ISNUMBER(P6)),L6-P6,"") | R6: =IF(AND(ISNUMBER(L6),ISNUMBER(P6)),L6+P6,"")
A7: 3 | B7: =AVERAGE(Transform!D4:D1004) | C7: =VAR(Transform!D4:D1004) | D7: =SQRT(C7) | E7: =COUNTA(Data!D4:D1004) | F7: =CONFIDENCE(D2,D7, E7) | G7: =B7-F7 | H7: =B7+F7 | K7: System | L7: =AVERAGE(Transform!B4:S1004) | M7: =VAR(Transform!B4:S1004) | N7: =SQRT(M7) | O7: =COUNT(Transform!B4:S1004) | P7: =IF(AND(ISNUMBER(N7),O7>0),CONFIDENCE(D2,N7,O7),"") | Q7: =IF(AND(ISNUMBER(L7),ISNUMBER(P7)),L7-P7,"") | R7: =IF(AND(ISNUMBER(L7),ISNUMBER(P7)),L7+P7,"")
A8: 4 | B8: =AVERAGE(Transform!E4:E1004) | C8: =VAR(Transform!E4:E1004) | D8: =SQRT(C8) | E8: =COUNTA(Data!E4:E1004) | F8: =CONFIDENCE(D2,D8, E8) | G8: =B8-F8 | H8: =B8+F8
A9: 5 | B9: =AVERAGE(Transform!F4:F1004) | C9: =VAR(Transform!F4:F1004) | D9: =SQRT(C9) | E9: =COUNTA(Data!F4:F1004) | F9: =CONFIDENCE(D2,D9, E9) | G9: =B9-F9 | H9: =B9+F9
A10: 6 | B10: =AVERAGE(Transform!G4:G1004) | C10: =VAR(Transform!G4:G1004) | D10: =SQRT(C10) | E10: =COUNTA(Data!G4:G1004) | F10: =CONFIDENCE(D2,D10, E10) | G10: =B10-F10 | H10: =B10+F10 | K10: XEQ Scores By Stakeholder
A11: 7 | B11: =AVERAGE(Transform!H4:H1004) | C11: =VAR(Transform!H4:H1004) | D11: =SQRT(C11) | E11: =COUNTA(Data!H4:H1004) | F11: =CONFIDENCE(D2,D11, E11) | G11: =B11-F11 | H11: =B11+F11 | K11: Stakeholder | L11: Utility Mean | M11: Utility Variance | N11: Utility Std. Dev. | O11: Utility No. | P11: Utility Confidence | Q11: Utility Confidence Interval | S11: Satisfaction Mean | T11: Satisfaction Variance | U11: Satisfaction Std. Dev. | V11: Satisfaction No. | W11: Satisfaction Confidence | X11: Satisfaction Confidence Interval | Z11: Effectiveness Mean | AA11: Effectiveness Variance | AB11: Effectiveness Std. Dev. | AC11: Effectiveness No. | AD11: Effectiveness Confidence | AE11: Effectiveness Confidence Interval | AN11: System Mean | AO11: System Variance | AP11: System Std. Dev. | AQ11: System No. | AR11: System Confidence | AS11: System Confidence Interval
A12: 8 | B12: =AVERAGE(Transform!I4:I1004) | C12: =VAR(Transform!I4:I1004) | D12: =SQRT(C12) | E12: =COUNTA(Data!I4:I1004) | F12: =CONFIDENCE(D2,D12, E12) | G12: =B12-F12 | H12: =B12+F12 | K12: {=_xlfn._xlws.FILTER(Stakeholders!A3:A50, Stakeholders!A3:A50<>"")} | L12: =IFERROR(AVERAGEIF(Transform!$A$4:$A$1004,Transform!AI4,Transform!$V$4:$V$1004),"") | M12: =IFERROR(VAR(FILTER(Transform!$V$4:$V$1004,Transform!$A$4:$A$1004=Transform!AI4)),"") | N12: =IF(ISNUMBER(M12),SQRT(M12),"") | O12: =COUNT(FILTER(Transform!$V$4:$V$1004,Transform!$A$4:$A$1004=Transform!AI4)) | P12: =IF(AND(ISNUMBER(N12),O12>0),CONFIDENCE($D$2,N12,O12),"") | Q12: =IF(AND(ISNUMBER(L12),ISNUMBER(P12)),L12-P12,"") | R12: =IF(AND(ISNUMBER(L12),ISNUMBER(P12)),L12+P12,"") | S12: =IFERROR(AVERAGEIF(Transform!$A$4:$A$1004,Transform!AI4,Transform!$W$4:$W$1004),"") | T12: =IFERROR(VAR(FILTER(Transform!$W$4:$W$1004,Transform!$A$4:$A$1004=Transform!AI4)),"") | U12: =IF(ISNUMBER(T12),SQRT(T12),"") | V12: =COUNT(FILTER(Transform!$W$4:$W$1004,Transform!$A$4:$A$1004=Transform!AI4)) | W12: =IF(AND(ISNUMBER(U12),V12>0),CONFIDENCE($D$2,U12,V12),"") | X12: =IF(AND(ISNUMBER(S12),ISNUMBER(W12)),S12-W12,"") | Y12: =IF(AND(ISNUMBER(S12),ISNUMBER(W12)),S12+W12,"") | Z12: =IFERROR(AVERAGEIF(Transform!$A$4:$A$1004,Transform!AI4,Transform!$X$4:$X$1004),"") | AA12: =IFERROR(VAR(FILTER(Transform!$X$4:$X$1004,Transform!$A$4:$A$1004=Transform!AI4)),"") | AB12: =IF(ISNUMBER(AA12),SQRT(AA12),"") | AC12: =COUNT(FILTER(Transform!$X$4:$X$1004,Transform!$A$4:$A$1004=Transform!AI4)) | AD12: =IF(AND(ISNUMBER(AB12),AC12>0),CONFIDENCE($D$2,AB12,AC12),"") | AE12: =IF(AND(ISNUMBER(Z12),ISNUMBER(AD12)),Z12-AD12,"") | AF12: =IF(AND(ISNUMBER(Z12),ISNUMBER(AD12)),Z12+AD12,"") | AN12: =IFERROR(AVERAGEIF(Transform!$A$4:$A$1004,Transform!AI4,Transform!$B$4:$S$1004),"") | AO12: =IFERROR(VAR(FILTER(Transform!$B$4:$S$1004,Transform!$A$4:$A$1004=Transform!AI4)),"") | AP12: =IF(ISNUMBER(AO12),SQRT(AO12),"") | AQ12: =COUNT(FILTER(Transform!$B$4:$S$1004,Transform!$A$4:$A$1004=Transform!AI4)) | AR12: =IF(AND(ISNUMBER(AP12),AQ12>0),CONFIDENCE($D$2,AP12,AQ12),"") | AS12: =IF(AND(ISNUMBER(AN12),ISNUMBER(AR12)),AN12-AR12,"") | AT12: =IF(AND(ISNUMBER(AN12),ISNUMBER(AR12)),AN12+AR12,"")
A13: 9 | B13: =AVERAGE(Transform!J4:J1004) | C13: =VAR(Transform!J4:J1004) | D13: =SQRT(C13) | E13: =COUNTA(Data!J4:J1004) | F13: =CONFIDENCE(D2,D13, E13) | G13: =B13-F13 | H13: =B13+F13 | K13: Student | L13: =IFERROR(AVERAGEIF(Transform!$A$4:$A$1004,Transform!AI5,Transform!$V$4:$V$1004),"") | M13: =IFERROR(VAR(FILTER(Transform!$V$4:$V$1004,Transform!$A$4:$A$1004=Transform!AI5)),"") | N13: =IF(ISNUMBER(M13),SQRT(M13),"") | O13: =COUNT(FILTER(Transform!$V$4:$V$1004,Transform!$A$4:$A$1004=Transform!AI5)) | P13: =IF(AND(ISNUMBER(N13),O13>0),CONFIDENCE($D$2,N13,O13),"") | Q13: =IF(AND(ISNUMBER(L13),ISNUMBER(P13)),L13-P13,"") | R13: =IF(AND(ISNUMBER(L13),ISNUMBER(P13)),L13+P13,"") | S13: =IFERROR(AVERAGEIF(Transform!$A$4:$A$1004,Transform!AI5,Transform!$W$4:$W$1004),"") | T13: =IFERROR(VAR(FILTER(Transform!$W$4:$W$1004,Transform!$A$4:$A$1004=Transform!AI5)),"") | U13: =IF(ISNUMBER(T13),SQRT(T13),"") | V13: =COUNT(FILTER(Transform!$W$4:$W$1004,Transform!$A$4:$A$1004=Transform!AI5)) | W13: =IF(AND(ISNUMBER(U13),V13>0),CONFIDENCE($D$2,U13,V13),"") | X13: =IF(AND(ISNUMBER(S13),ISNUMBER(W13)),S13-W13,"") | Y13: =IF(AND(ISNUMBER(S13),ISNUMBER(W13)),S13+W13,"") | Z13: =IFERROR(AVERAGEIF(Transform!$A$4:$A$1004,Transform!AI5,Transform!$X$4:$X$1004),"") | AA13: =IFERROR(VAR(FILTER(Transform!$X$4:$X$1004,Transform!$A$4:$A$1004=Transform!AI5)),"") | AB13: =IF(ISNUMBER(AA13),SQRT(AA13),"") | AC13: =COUNT(FILTER(Transform!$X$4:$X$1004,Transform!$A$4:$A$1004=Transform!AI5)) | AD13: =IF(AND(ISNUMBER(AB13),AC13>0),CONFIDENCE($D$2,AB13,AC13),"") | AE13: =IF(AND(ISNUMBER(Z13),ISNUMBER(AD13)),Z13-AD13,"") | AF13: =IF(AND(ISNUMBER(Z13),ISNUMBER(AD13)),Z13+AD13,"") | AN13: =IFERROR(AVERAGEIF(Transform!$A$4:$A$1004,Transform!AI5,Transform!$B$4:$S$1004),"") | AO13: =IFERROR(VAR(FILTER(Transform!$B$4:$S$1004,Transform!$A$4:$A$1004=Transform!AI5)),"") | AP13: =IF(ISNUMBER(AO13),SQRT(AO13),"") | AQ13: =COUNT(FILTER(Transform!$B$4:$S$1004,Transform!$A$4:$A$1004=Transform!AI5)) | AR13: =IF(AND(ISNUMBER(AP13),AQ13>0),CONFIDENCE($D$2,AP13,AQ13),"") | AS13: =IF(AND(ISNUMBER(AN13),ISNUMBER(AR13)),AN13-AR13,"") | AT13: =IF(AND(ISNUMBER(AN13),ISNUMBER(AR13)),AN13+AR13,"")
A14: 10 | B14: =AVERAGE(Transform!K4:K1004) | C14: =VAR(Transform!K4:K1004) | D14: =SQRT(C14) | E14: =COUNTA(Data!K4:K1004) | F14: =CONFIDENCE(D2,D14, E14) | G14: =B14-F14 | H14: =B14+F14 | K14: Admin Assistant | L14: =IFERROR(AVERAGEIF(Transform!$A$4:$A$1004,Transform!AI6,Transform!$V$4:$V$1004),"") | M14: =IFERROR(VAR(FILTER(Transform!$V$4:$V$1004,Transform!$A$4:$A$1004=Transform!AI6)),"") | N14: =IF(ISNUMBER(M14),SQRT(M14),"") | O14: =COUNT(FILTER(Transform!$V$4:$V$1004,Transform!$A$4:$A$1004=Transform!AI6)) | P14: =IF(AND(ISNUMBER(N14),O14>0),CONFIDENCE($D$2,N14,O14),"") | Q14: =IF(AND(ISNUMBER(L14),ISNUMBER(P14)),L14-P14,"") | R14: =IF(AND(ISNUMBER(L14),ISNUMBER(P14)),L14+P14,"") | S14: =IFERROR(AVERAGEIF(Transform!$A$4:$A$1004,Transform!AI6,Transform!$W$4:$W$1004),"") | T14: =IFERROR(VAR(FILTER(Transform!$W$4:$W$1004,Transform!$A$4:$A$1004=Transform!AI6)),"") | U14: =IF(ISNUMBER(T14),SQRT(T14),"") | V14: =COUNT(FILTER(Transform!$W$4:$W$1004,Transform!$A$4:$A$1004=Transform!AI6)) | W14: =IF(AND(ISNUMBER(U14),V14>0),CONFIDENCE($D$2,U14,V14),"") | X14: =IF(AND(ISNUMBER(S14),ISNUMBER(W14)),S14-W14,"") | Y14: =IF(AND(ISNUMBER(S14),ISNUMBER(W14)),S14+W14,"") | Z14: =IFERROR(AVERAGEIF(Transform!$A$4:$A$1004,Transform!AI6,Transform!$X$4:$X$1004),"") | AA14: =IFERROR(VAR(FILTER(Transform!$X$4:$X$1004,Transform!$A$4:$A$1004=Transform!AI6)),"") | AB14: =IF(ISNUMBER(AA14),SQRT(AA14),"") | AC14: =COUNT(FILTER(Transform!$X$4:$X$1004,Transform!$A$4:$A$1004=Transform!AI6)) | AD14: =IF(AND(ISNUMBER(AB14),AC14>0),CONFIDENCE($D$2,AB14,AC14),"") | AE14: =IF(AND(ISNUMBER(Z14),ISNUMBER(AD14)),Z14-AD14,"") | AF14: =IF(AND(ISNUMBER(Z14),ISNUMBER(AD14)),Z14+AD14,"") | AN14: =IFERROR(AVERAGEIF(Transform!$A$4:$A$1004,Transform!AI6,Transform!$B$4:$S$1004),"") | AO14: =IFERROR(VAR(FILTER(Transform!$B$4:$S$1004,Transform!$A$4:$A$1004=Transform!AI6)),"") | AP14: =IF(ISNUMBER(AO14),SQRT(AO14),"") | AQ14: =COUNT(FILTER(Transform!$B$4:$S$1004,Transform!$A$4:$A$1004=Transform!AI6)) | AR14: =IF(AND(ISNUMBER(AP14),AQ14>0),CONFIDENCE($D$2,AP14,AQ14),"") | AS14: =IF(AND(ISNUMBER(AN14),ISNUMBER(AR14)),AN14-AR14,"") | AT14: =IF(AND(ISNUMBER(AN14),ISNUMBER(AR14)),AN14+AR14,"")
A15: 11 | B15: =AVERAGE(Transform!L4:L1004) | C15: =VAR(Transform!L4:L1004) | D15: =SQRT(C15) | E15: =COUNTA(Data!L4:L1004) | F15: =CONFIDENCE(D2,D15, E15) | G15: =B15-F15 | H15: =B15+F15 | K15: Demonstrator | L15: =IFERROR(AVERAGEIF(Transform!$A$4:$A$1004,Transform!AI7,Transform!$V$4:$V$1004),"") | M15: =IFERROR(VAR(FILTER(Transform!$V$4:$V$1004,Transform!$A$4:$A$1004=Transform!AI7)),"") | N15: =IF(ISNUMBER(M15),SQRT(M15),"") | O15: =COUNT(FILTER(Transform!$V$4:$V$1004,Transform!$A$4:$A$1004=Transform!AI7)) | P15: =IF(AND(ISNUMBER(N15),O15>0),CONFIDENCE($D$2,N15,O15),"") | Q15: =IF(AND(ISNUMBER(L15),ISNUMBER(P15)),L15-P15,"") | R15: =IF(AND(ISNUMBER(L15),ISNUMBER(P15)),L15+P15,"") | S15: =IFERROR(AVERAGEIF(Transform!$A$4:$A$1004,Transform!AI7,Transform!$W$4:$W$1004),"") | T15: =IFERROR(VAR(FILTER(Transform!$W$4:$W$1004,Transform!$A$4:$A$1004=Transform!AI7)),"") | U15: =IF(ISNUMBER(T15),SQRT(T15),"") | V15: =COUNT(FILTER(Transform!$W$4:$W$1004,Transform!$A$4:$A$1004=Transform!AI7)) | W15: =IF(AND(ISNUMBER(U15),V15>0),CONFIDENCE($D$2,U15,V15),"") | X15: =IF(AND(ISNUMBER(S15),ISNUMBER(W15)),S15-W15,"") | Y15: =IF(AND(ISNUMBER(S15),ISNUMBER(W15)),S15+W15,"") | Z15: =IFERROR(AVERAGEIF(Transform!$A$4:$A$1004,Transform!AI7,Transform!$X$4:$X$1004),"") | AA15: =IFERROR(VAR(FILTER(Transform!$X$4:$X$1004,Transform!$A$4:$A$1004=Transform!AI7)),"") | AB15: =IF(ISNUMBER(AA15),SQRT(AA15),"") | AC15: =COUNT(FILTER(Transform!$X$4:$X$1004,Transform!$A$4:$A$1004=Transform!AI7)) | AD15: =IF(AND(ISNUMBER(AB15),AC15>0),CONFIDENCE($D$2,AB15,AC15),"") | AE15: =IF(AND(ISNUMBER(Z15),ISNUMBER(AD15)),Z15-AD15,"") | AF15: =IF(AND(ISNUMBER(Z15),ISNUMBER(AD15)),Z15+AD15,"") | AN15: =IFERROR(AVERAGEIF(Transform!$A$4:$A$1004,Transform!AI7,Transform!$B$4:$S$1004),"") | AO15: =IFERROR(VAR(FILTER(Transform!$B$4:$S$1004,Transform!$A$4:$A$1004=Transform!AI7)),"") | AP15: =IF(ISNUMBER(AO15),SQRT(AO15),"") | AQ15: =COUNT(FILTER(Transform!$B$4:$S$1004,Transform!$A$4:$A$1004=Transform!AI7)) | AR15: =IF(AND(ISNUMBER(AP15),AQ15>0),CONFIDENCE($D$2,AP15,AQ15),"") | AS15: =IF(AND(ISNUMBER(AN15),ISNUMBER(AR15)),AN15-AR15,"") | AT15: =IF(AND(ISNUMBER(AN15),ISNUMBER(AR15)),AN15+AR15,"")
A16: 12 | B16: =AVERAGE(Transform!M4:M1004) | C16: =VAR(Transform!M4:M1004) | D16: =SQRT(C16) | E16: =COUNTA(Data!M4:M1004) | F16: =CONFIDENCE(D2,D16, E16) | G16: =B16-F16 | H16: =B16+F16 | L16: =IFERROR(AVERAGEIF(Transform!$A$4:$A$1004,Transform!AI8,Transform!$V$4:$V$1004),"") | M16: =IFERROR(VAR(FILTER(Transform!$V$4:$V$1004,Transform!$A$4:$A$1004=Transform!AI8)),"") | N16: =IF(ISNUMBER(M16),SQRT(M16),"") | O16: =COUNT(FILTER(Transform!$V$4:$V$1004,Transform!$A$4:$A$1004=Transform!AI8)) | P16: =IF(AND(ISNUMBER(N16),O16>0),CONFIDENCE($D$2,N16,O16),"") | Q16: =IF(AND(ISNUMBER(L16),ISNUMBER(P16)),L16-P16,"") | R16: =IF(AND(ISNUMBER(L16),ISNUMBER(P16)),L16+P16,"") | S16: =IFERROR(AVERAGEIF(Transform!$A$4:$A$1004,Transform!AI8,Transform!$W$4:$W$1004),"") | T16: =IFERROR(VAR(FILTER(Transform!$W$4:$W$1004,Transform!$A$4:$A$1004=Transform!AI8)),"") | U16: =IF(ISNUMBER(T16),SQRT(T16),"") | V16: =COUNT(FILTER(Transform!$W$4:$W$1004,Transform!$A$4:$A$1004=Transform!AI8)) | W16: =IF(AND(ISNUMBER(U16),V16>0),CONFIDENCE($D$2,U16,V16),"") | X16: =IF(AND(ISNUMBER(S16),ISNUMBER(W16)),S16-W16,"") | Y16: =IF(AND(ISNUMBER(S16),ISNUMBER(W16)),S16+W16,"") | Z16: =IFERROR(AVERAGEIF(Transform!$A$4:$A$1004,Transform!AI8,Transform!$X$4:$X$1004),"") | AA16: =IFERROR(VAR(FILTER(Transform!$X$4:$X$1004,Transform!$A$4:$A$1004=Transform!AI8)),"") | AB16: =IF(ISNUMBER(AA16),SQRT(AA16),"") | AC16: =COUNT(FILTER(Transform!$X$4:$X$1004,Transform!$A$4:$A$1004=Transform!AI8)) | AD16: =IF(AND(ISNUMBER(AB16),AC16>0),CONFIDENCE($D$2,AB16,AC16),"") | AE16: =IF(AND(ISNUMBER(Z16),ISNUMBER(AD16)),Z16-AD16,"") | AF16: =IF(AND(ISNUMBER(Z16),ISNUMBER(AD16)),Z16+AD16,"") | AN16: =IFERROR(AVERAGEIF(Transform!$A$4:$A$1004,Transform!AI8,Transform!$B$4:$S$1004),"") | AO16: =IFERROR(VAR(FILTER(Transform!$B$4:$S$1004,Transform!$A$4:$A$1004=Transform!AI8)),"") | AP16: =IF(ISNUMBER(AO16),SQRT(AO16),"") | AQ16: =COUNT(FILTER(Transform!$B$4:$S$1004,Transform!$A$4:$A$1004=Transform!AI8)) | AR16: =IF(AND(ISNUMBER(AP16),AQ16>0),CONFIDENCE($D$2,AP16,AQ16),"") | AS16: =IF(AND(ISNUMBER(AN16),ISNUMBER(AR16)),AN16-AR16,"") | AT16: =IF(AND(ISNUMBER(AN16),ISNUMBER(AR16)),AN16+AR16,"")
A17: 13 | B17: =AVERAGE(Transform!N4:N1004) | C17: =VAR(Transform!N4:N1004) | D17: =SQRT(C17) | E17: =COUNTA(Data!N4:N1004) | F17: =CONFIDENCE(D2,D17, E17) | G17: =B17-F17 | H17: =B17+F17 | L17: =IFERROR(AVERAGEIF(Transform!$A$4:$A$1004,Transform!AI9,Transform!$V$4:$V$1004),"") | M17: =IFERROR(VAR(FILTER(Transform!$V$4:$V$1004,Transform!$A$4:$A$1004=Transform!AI9)),"") | N17: =IF(ISNUMBER(M17),SQRT(M17),"") | O17: =COUNT(FILTER(Transform!$V$4:$V$1004,Transform!$A$4:$A$1004=Transform!AI9)) | P17: =IF(AND(ISNUMBER(N17),O17>0),CONFIDENCE($D$2,N17,O17),"") | Q17: =IF(AND(ISNUMBER(L17),ISNUMBER(P17)),L17-P17,"") | R17: =IF(AND(ISNUMBER(L17),ISNUMBER(P17)),L17+P17,"") | S17: =IFERROR(AVERAGEIF(Transform!$A$4:$A$1004,Transform!AI9,Transform!$W$4:$W$1004),"") | T17: =IFERROR(VAR(FILTER(Transform!$W$4:$W$1004,Transform!$A$4:$A$1004=Transform!AI9)),"") | U17: =IF(ISNUMBER(T17),SQRT(T17),"") | V17: =COUNT(FILTER(Transform!$W$4:$W$1004,Transform!$A$4:$A$1004=Transform!AI9)) | W17: =IF(AND(ISNUMBER(U17),V17>0),CONFIDENCE($D$2,U17,V17),"") | X17: =IF(AND(ISNUMBER(S17),ISNUMBER(W17)),S17-W17,"") | Y17: =IF(AND(ISNUMBER(S17),ISNUMBER(W17)),S17+W17,"") | Z17: =IFERROR(AVERAGEIF(Transform!$A$4:$A$1004,Transform!AI9,Transform!$X$4:$X$1004),"") | AA17: =IFERROR(VAR(FILTER(Transform!$X$4:$X$1004,Transform!$A$4:$A$1004=Transform!AI9)),"") | AB17: =IF(ISNUMBER(AA17),SQRT(AA17),"") | AC17: =COUNT(FILTER(Transform!$X$4:$X$1004,Transform!$A$4:$A$1004=Transform!AI9)) | AD17: =IF(AND(ISNUMBER(AB17),AC17>0),CONFIDENCE($D$2,AB17,AC17),"") | AE17: =IF(AND(ISNUMBER(Z17),ISNUMBER(AD17)),Z17-AD17,"") | AF17: =IF(AND(ISNUMBER(Z17),ISNUMBER(AD17)),Z17+AD17,"") | AN17: =IFERROR(AVERAGEIF(Transform!$A$4:$A$1004,Transform!AI9,Transform!$B$4:$S$1004),"") | AO17: =IFERROR(VAR(FILTER(Transform!$B$4:$S$1004,Transform!$A$4:$A$1004=Transform!AI9)),"") | AP17: =IF(ISNUMBER(AO17),SQRT(AO17),"") | AQ17: =COUNT(FILTER(Transform!$B$4:$S$1004,Transform!$A$4:$A$1004=Transform!AI9)) | AR17: =IF(AND(ISNUMBER(AP17),AQ17>0),CONFIDENCE($D$2,AP17,AQ17),"") | AS17: =IF(AND(ISNUMBER(AN17),ISNUMBER(AR17)),AN17-AR17,"") | AT17: =IF(AND(ISNUMBER(AN17),ISNUMBER(AR17)),AN17+AR17,"")
A18: 14 | B18: =AVERAGE(Transform!O4:O1004) | C18: =VAR(Transform!O4:O1004) | D18: =SQRT(C18) | E18: =COUNTA(Data!O4:O1004) | F18: =CONFIDENCE(D2,D18, E18) | G18: =B18-F18 | H18: =B18+F18 | L18: =IFERROR(AVERAGEIF(Transform!$A$4:$A$1004,Transform!AI10,Transform!$V$4:$V$1004),"") | M18: =IFERROR(VAR(FILTER(Transform!$V$4:$V$1004,Transform!$A$4:$A$1004=Transform!AI10)),"") | N18: =IF(ISNUMBER(M18),SQRT(M18),"") | O18: =COUNT(FILTER(Transform!$V$4:$V$1004,Transform!$A$4:$A$1004=Transform!AI10)) | P18: =IF(AND(ISNUMBER(N18),O18>0),CONFIDENCE($D$2,N18,O18),"") | Q18: =IF(AND(ISNUMBER(L18),ISNUMBER(P18)),L18-P18,"") | R18: =IF(AND(ISNUMBER(L18),ISNUMBER(P18)),L18+P18,"") | S18: =IFERROR(AVERAGEIF(Transform!$A$4:$A$1004,Transform!AI10,Transform!$W$4:$W$1004),"") | T18: =IFERROR(VAR(FILTER(Transform!$W$4:$W$1004,Transform!$A$4:$A$1004=Transform!AI10)),"") | U18: =IF(ISNUMBER(T18),SQRT(T18),"") | V18: =COUNT(FILTER(Transform!$W$4:$W$1004,Transform!$A$4:$A$1004=Transform!AI10)) | W18: =IF(AND(ISNUMBER(U18),V18>0),CONFIDENCE($D$2,U18,V18),"") | X18: =IF(AND(ISNUMBER(S18),ISNUMBER(W18)),S18-W18,"") | Y18: =IF(AND(ISNUMBER(S18),ISNUMBER(W18)),S18+W18,"") | Z18: =IFERROR(AVERAGEIF(Transform!$A$4:$A$1004,Transform!AI10,Transform!$X$4:$X$1004),"") | AA18: =IFERROR(VAR(FILTER(Transform!$X$4:$X$1004,Transform!$A$4:$A$1004=Transform!AI10)),"") | AB18: =IF(ISNUMBER(AA18),SQRT(AA18),"") | AC18: =COUNT(FILTER(Transform!$X$4:$X$1004,Transform!$A$4:$A$1004=Transform!AI10)) | AD18: =IF(AND(ISNUMBER(AB18),AC18>0),CONFIDENCE($D$2,AB18,AC18),"") | AE18: =IF(AND(ISNUMBER(Z18),ISNUMBER(AD18)),Z18-AD18,"") | AF18: =IF(AND(ISNUMBER(Z18),ISNUMBER(AD18)),Z18+AD18,"") | AN18: =IFERROR(AVERAGEIF(Transform!$A$4:$A$1004,Transform!AI10,Transform!$B$4:$S$1004),"") | AO18: =IFERROR(VAR(FILTER(Transform!$B$4:$S$1004,Transform!$A$4:$A$1004=Transform!AI10)),"") | AP18: =IF(ISNUMBER(AO18),SQRT(AO18),"") | AQ18: =COUNT(FILTER(Transform!$B$4:$S$1004,Transform!$A$4:$A$1004=Transform!AI10)) | AR18: =IF(AND(ISNUMBER(AP18),AQ18>0),CONFIDENCE($D$2,AP18,AQ18),"") | AS18: =IF(AND(ISNUMBER(AN18),ISNUMBER(AR18)),AN18-AR18,"") | AT18: =IF(AND(ISNUMBER(AN18),ISNUMBER(AR18)),AN18+AR18,"")
A19: 15 | B19: =AVERAGE(Transform!P4:P1004) | C19: =VAR(Transform!P4:P1004) | D19: =SQRT(C19) | E19: =COUNTA(Data!P4:P1004) | F19: =CONFIDENCE(D2,D19, E19) | G19: =B19-F19 | H19: =B19+F19 | L19: =IFERROR(AVERAGEIF(Transform!$A$4:$A$1004,Transform!AI11,Transform!$V$4:$V$1004),"") | M19: =IFERROR(VAR(FILTER(Transform!$V$4:$V$1004,Transform!$A$4:$A$1004=Transform!AI11)),"") | N19: =IF(ISNUMBER(M19),SQRT(M19),"") | O19: =COUNT(FILTER(Transform!$V$4:$V$1004,Transform!$A$4:$A$1004=Transform!AI11)) | P19: =IF(AND(ISNUMBER(N19),O19>0),CONFIDENCE($D$2,N19,O19),"") | Q19: =IF(AND(ISNUMBER(L19),ISNUMBER(P19)),L19-P19,"") | R19: =IF(AND(ISNUMBER(L19),ISNUMBER(P19)),L19+P19,"") | S19: =IFERROR(AVERAGEIF(Transform!$A$4:$A$1004,Transform!AI11,Transform!$W$4:$W$1004),"") | T19: =IFERROR(VAR(FILTER(Transform!$W$4:$W$1004,Transform!$A$4:$A$1004=Transform!AI11)),"") | U19: =IF(ISNUMBER(T19),SQRT(T19),"") | V19: =COUNT(FILTER(Transform!$W$4:$W$1004,Transform!$A$4:$A$1004=Transform!AI11)) | W19: =IF(AND(ISNUMBER(U19),V19>0),CONFIDENCE($D$2,U19,V19),"") | X19: =IF(AND(ISNUMBER(S19),ISNUMBER(W19)),S19-W19,"") | Y19: =IF(AND(ISNUMBER(S19),ISNUMBER(W19)),S19+W19,"") | Z19: =IFERROR(AVERAGEIF(Transform!$A$4:$A$1004,Transform!AI11,Transform!$X$4:$X$1004),"") | AA19: =IFERROR(VAR(FILTER(Transform!$X$4:$X$1004,Transform!$A$4:$A$1004=Transform!AI11)),"") | AB19: =IF(ISNUMBER(AA19),SQRT(AA19),"") | AC19: =COUNT(FILTER(Transform!$X$4:$X$1004,Transform!$A$4:$A$1004=Transform!AI11)) | AD19: =IF(AND(ISNUMBER(AB19),AC19>0),CONFIDENCE($D$2,AB19,AC19),"") | AE19: =IF(AND(ISNUMBER(Z19),ISNUMBER(AD19)),Z19-AD19,"") | AF19: =IF(AND(ISNUMBER(Z19),ISNUMBER(AD19)),Z19+AD19,"") | AN19: =IFERROR(AVERAGEIF(Transform!$A$4:$A$1004,Transform!AI11,Transform!$B$4:$S$1004),"") | AO19: =IFERROR(VAR(FILTER(Transform!$B$4:$S$1004,Transform!$A$4:$A$1004=Transform!AI11)),"") | AP19: =IF(ISNUMBER(AO19),SQRT(AO19),"") | AQ19: =COUNT(FILTER(Transform!$B$4:$S$1004,Transform!$A$4:$A$1004=Transform!AI11)) | AR19: =IF(AND(ISNUMBER(AP19),AQ19>0),CONFIDENCE($D$2,AP19,AQ19),"") | AS19: =IF(AND(ISNUMBER(AN19),ISNUMBER(AR19)),AN19-AR19,"") | AT19: =IF(AND(ISNUMBER(AN19),ISNUMBER(AR19)),AN19+AR19,"")
A20: 16 | B20: =AVERAGE(Transform!Q4:Q1004) | C20: =VAR(Transform!Q4:Q1004) | D20: =SQRT(C20) | E20: =COUNTA(Data!Q4:Q1004) | F20: =CONFIDENCE(D2,D20, E20) | G20: =B20-F20 | H20: =B20+F20 | L20: =IFERROR(AVERAGEIF(Transform!$A$4:$A$1004,Transform!AI12,Transform!$V$4:$V$1004),"") | M20: =IFERROR(VAR(FILTER(Transform!$V$4:$V$1004,Transform!$A$4:$A$1004=Transform!AI12)),"") | N20: =IF(ISNUMBER(M20),SQRT(M20),"") | O20: =COUNT(FILTER(Transform!$V$4:$V$1004,Transform!$A$4:$A$1004=Transform!AI12)) | P20: =IF(AND(ISNUMBER(N20),O20>0),CONFIDENCE($D$2,N20,O20),"") | Q20: =IF(AND(ISNUMBER(L20),ISNUMBER(P20)),L20-P20,"") | R20: =IF(AND(ISNUMBER(L20),ISNUMBER(P20)),L20+P20,"") | S20: =IFERROR(AVERAGEIF(Transform!$A$4:$A$1004,Transform!AI12,Transform!$W$4:$W$1004),"") | T20: =IFERROR(VAR(FILTER(Transform!$W$4:$W$1004,Transform!$A$4:$A$1004=Transform!AI12)),"") | U20: =IF(ISNUMBER(T20),SQRT(T20),"") | V20: =COUNT(FILTER(Transform!$W$4:$W$1004,Transform!$A$4:$A$1004=Transform!AI12)) | W20: =IF(AND(ISNUMBER(U20),V20>0),CONFIDENCE($D$2,U20,V20),"") | X20: =IF(AND(ISNUMBER(S20),ISNUMBER(W20)),S20-W20,"") | Y20: =IF(AND(ISNUMBER(S20),ISNUMBER(W20)),S20+W20,"") | Z20: =IFERROR(AVERAGEIF(Transform!$A$4:$A$1004,Transform!AI12,Transform!$X$4:$X$1004),"") | AA20: =IFERROR(VAR(FILTER(Transform!$X$4:$X$1004,Transform!$A$4:$A$1004=Transform!AI12)),"") | AB20: =IF(ISNUMBER(AA20),SQRT(AA20),"") | AC20: =COUNT(FILTER(Transform!$X$4:$X$1004,Transform!$A$4:$A$1004=Transform!AI12)) | AD20: =IF(AND(ISNUMBER(AB20),AC20>0),CONFIDENCE($D$2,AB20,AC20),"") | AE20: =IF(AND(ISNUMBER(Z20),ISNUMBER(AD20)),Z20-AD20,"") | AF20: =IF(AND(ISNUMBER(Z20),ISNUMBER(AD20)),Z20+AD20,"") | AN20: =IFERROR(AVERAGEIF(Transform!$A$4:$A$1004,Transform!AI12,Transform!$B$4:$S$1004),"") | AO20: =IFERROR(VAR(FILTER(Transform!$B$4:$S$1004,Transform!$A$4:$A$1004=Transform!AI12)),"") | AP20: =IF(ISNUMBER(AO20),SQRT(AO20),"") | AQ20: =COUNT(FILTER(Transform!$B$4:$S$1004,Transform!$A$4:$A$1004=Transform!AI12)) | AR20: =IF(AND(ISNUMBER(AP20),AQ20>0),CONFIDENCE($D$2,AP20,AQ20),"") | AS20: =IF(AND(ISNUMBER(AN20),ISNUMBER(AR20)),AN20-AR20,"") | AT20: =IF(AND(ISNUMBER(AN20),ISNUMBER(AR20)),AN20+AR20,"")
A21: 17 | B21: =AVERAGE(Transform!R4:R1004) | C21: =VAR(Transform!R4:R1004) | D21: =SQRT(C21) | E21: =COUNTA(Data!R4:R1004) | F21: =CONFIDENCE(D2,D21, E21) | G21: =B21-F21 | H21: =B21+F21 | L21: =IFERROR(AVERAGEIF(Transform!$A$4:$A$1004,Transform!AI13,Transform!$V$4:$V$1004),"") | M21: =IFERROR(VAR(FILTER(Transform!$V$4:$V$1004,Transform!$A$4:$A$1004=Transform!AI13)),"") | N21: =IF(ISNUMBER(M21),SQRT(M21),"") | O21: =COUNT(FILTER(Transform!$V$4:$V$1004,Transform!$A$4:$A$1004=Transform!AI13)) | P21: =IF(AND(ISNUMBER(N21),O21>0),CONFIDENCE($D$2,N21,O21),"") | Q21: =IF(AND(ISNUMBER(L21),ISNUMBER(P21)),L21-P21,"") | R21: =IF(AND(ISNUMBER(L21),ISNUMBER(P21)),L21+P21,"") | S21: =IFERROR(AVERAGEIF(Transform!$A$4:$A$1004,Transform!AI13,Transform!$W$4:$W$1004),"") | T21: =IFERROR(VAR(FILTER(Transform!$W$4:$W$1004,Transform!$A$4:$A$1004=Transform!AI13)),"") | U21: =IF(ISNUMBER(T21),SQRT(T21),"") | V21: =COUNT(FILTER(Transform!$W$4:$W$1004,Transform!$A$4:$A$1004=Transform!AI13)) | W21: =IF(AND(ISNUMBER(U21),V21>0),CONFIDENCE($D$2,U21,V21),"") | X21: =IF(AND(ISNUMBER(S21),ISNUMBER(W21)),S21-W21,"") | Y21: =IF(AND(ISNUMBER(S21),ISNUMBER(W21)),S21+W21,"") | Z21: =IFERROR(AVERAGEIF(Transform!$A$4:$A$1004,Transform!AI13,Transform!$X$4:$X$1004),"") | AA21: =IFERROR(VAR(FILTER(Transform!$X$4:$X$1004,Transform!$A$4:$A$1004=Transform!AI13)),"") | AB21: =IF(ISNUMBER(AA21),SQRT(AA21),"") | AC21: =COUNT(FILTER(Transform!$X$4:$X$1004,Transform!$A$4:$A$1004=Transform!AI13)) | AD21: =IF(AND(ISNUMBER(AB21),AC21>0),CONFIDENCE($D$2,AB21,AC21),"") | AE21: =IF(AND(ISNUMBER(Z21),ISNUMBER(AD21)),Z21-AD21,"") | AF21: =IF(AND(ISNUMBER(Z21),ISNUMBER(AD21)),Z21+AD21,"") | AN21: =IFERROR(AVERAGEIF(Transform!$A$4:$A$1004,Transform!AI13,Transform!$B$4:$S$1004),"") | AO21: =IFERROR(VAR(FILTER(Transform!$B$4:$S$1004,Transform!$A$4:$A$1004=Transform!AI13)),"") | AP21: =IF(ISNUMBER(AO21),SQRT(AO21),"") | AQ21: =COUNT(FILTER(Transform!$B$4:$S$1004,Transform!$A$4:$A$1004=Transform!AI13)) | AR21: =IF(AND(ISNUMBER(AP21),AQ21>0),CONFIDENCE($D$2,AP21,AQ21),"") | AS21: =IF(AND(ISNUMBER(AN21),ISNUMBER(AR21)),AN21-AR21,"") | AT21: =IF(AND(ISNUMBER(AN21),ISNUMBER(AR21)),AN21+AR21,"")
